Workbook

Sheet INDEX
C2: Group No. | D2: Parag Milk Foods Limited
C4: Details of group members
C5: Name | D5: ID
C6: Adya Srivastava | D6: 2022A3PS0467P
C7: Priyan Hemil Mody | D7: 2020B3AA1964P
C8: Shreeram Petkar | D8: 2020B3A21966P
B13: Index
B14: Question
B15: I (a) | C15: Historical Data Daily
B16: I (a) | C16: Historical Data Monthly
B17: I (a) | C17: NIFTY 50
B18: I (a) | C18: Descriptive Stats
B19: I (a) | C19: Technical Analysis
B20: I (b) | C20: Balance Sheet
B21: I (b) | C21: Income Statement
B22: I (b) | C22: Ratio Analysis
B23: I (b) | C23: Company Stock Analysis
B24: II. | C24: Portfolio Analysis

Sheet Historical Data Daily
A1: Date | B1: Open | C1: High | D1: Low | E1: Close | F1: Adj Close | G1: Volume | H1: Normalised Volume | I1: HPR | J1: HPY | K1: Daily Range | L1: Normalised Daily Range | M1: CHG% | N1: Normalised CHG% | O1: CHG % of NIFTY 50 | P1: News Event | U1: 3 Year Bond Yield
A2: 44287 | B2: 106.5 | C2: 112 | D2: 105.95 | E2: 111.45 | F2: 111.03085 | G2: 1193557 | H2: =(G2-'Descriptive Stats'!$B$55)/('Descriptive Stats'!$B$56-'Descriptive Stats'!$B$55) -> 0.063914066 | K2: =C2-D2 -> 6.050003 | L2: =(K2-'Descriptive Stats'!$B$60)/('Descriptive Stats'!$B$61-'Descriptive Stats'!$B$60) -> 0.14804083 | Q2: 0 | U2: Date | V2: Price | W2: Open | X2: High | Y2: Low
A3: 44291 | B3: 114.05 | C3: 116.8 | D3: 107.5 | E3: 115.75 | F3: 115.31468 | G3: 3656668 | H3: =(G3-'Descriptive Stats'!$B$55)/('Descriptive Stats'!$B$56-'Descriptive Stats'!$B$55) -> 0.20247065 | I3: =E3/E2 -> 1.0385824 | J3: =I3-1 -> 0.038582352 | K3: =C3-D3 -> 9.300003 | L3: =(K3-'Descriptive Stats'!$B$60)/('Descriptive Stats'!$B$61-'Descriptive Stats'!$B$60) -> 0.24238046 | M3: =((E3-E2)/E2)*100 -> 3.8582352 | N3: =(M3-'Descriptive Stats'!$B$65)/('Descriptive Stats'!$B$66-'Descriptive Stats'!$B$65) -> 0.53400733 | O3: =((G3-G2)/G2)*100 -> 206.36727 | Q3: 0 | U3: 28/03/24 | V3: 7.052 | W3: 7.031 | X3: 7.055 | Y3: 7.031
A4: 44292 | B4: 115.8 | C4: 118.25 | D4: 112.4 | E4: 115.7 | F4: 115.26487 | G4: 1243382 | H4: =(G4-'Descriptive Stats'!$B$55)/('Descriptive Stats'!$B$56-'Descriptive Stats'!$B$55) -> 0.066716855 | I4: =E4/E3 -> 0.99956801 | J4: =I4-1 -> -0.00043199136 | K4: =C4-D4 -> 5.849998 | L4: =(K4-'Descriptive Stats'!$B$60)/('Descriptive Stats'!$B$61-'Descriptive Stats'!$B$60) -> 0.14223516 | M4: =((E4-E3)/E3)*100 -> -0.043199136 | N4: =(M4-'Descriptive Stats'!$B$65)/('Descriptive Stats'!$B$66-'Descriptive Stats'!$B$65) -> 0.38735158 | O4: =((G4-G3)/G3)*100 -> -65.996858 | Q4: 0 | U4: 27/03/24 | V4: 7.072 | W4: 7.097 | X4: 7.097 | Y4: 7.067
A5: 44293 | B5: 116.45 | C5: 118.05 | D5: 114.5 | E5: 114.9 | F5: 114.46788 | G5: 636056 | H5: =(G5-'Descriptive Stats'!$B$55)/('Descriptive Stats'!$B$56-'Descriptive Stats'!$B$55) -> 0.032553142 | I5: =E5/E4 -> 0.99308561 | J5: =I5-1 -> -0.0069143908 | K5: =C5-D5 -> 3.550003 | L5: =(K5-'Descriptive Stats'!$B$60)/('Descriptive Stats'!$B$61-'Descriptive Stats'!$B$60) -> 0.075471879 | M5: =((E5-E4)/E4)*100 -> -0.69143908 | N5: =(M5-'Descriptive Stats'!$B$65)/('Descriptive Stats'!$B$66-'Descriptive Stats'!$B$65) -> 0.3629841 | O5: =((G5-G4)/G4)*100 -> -48.844683 | Q5: 0 | U5: 26/03/24 | V5: 7.089 | W5: 7.091 | X5: 7.1 | Y5: 7.079
A6: 44294 | B6: 115.85 | C6: 118.2 | D6: 115 | E6: 116.15 | F6: 115.71318 | G6: 1332806 | H6: =(G6-'Descriptive Stats'!$B$55)/('Descriptive Stats'!$B$56-'Descriptive Stats'!$B$55) -> 0.071747195 | I6: =E6/E5 -> 1.010879 | J6: =I6-1 -> 0.010879025 | K6: =C6-D6 -> 3.199997 | L6: =(K6-'Descriptive Stats'!$B$60)/('Descriptive Stats'!$B$61-'Descriptive Stats'!$B$60) -> 0.065312052 | M6: =((E6-E5)/E5)*100 -> 1.0879025 | N6: =(M6-'Descriptive Stats'!$B$65)/('Descriptive Stats'!$B$66-'Descriptive Stats'!$B$65) -> 0.42986993 | O6: =((G6-G5)/G5)*100 -> 109.54224 | Q6: 0 | U6: 22/03/24 | V6: 7.087 | W6: 7.062 | X6: 7.096 | Y6: 7.055
A7: 44295 | B7: 116 | C7: 121.25 | D7: 115.05 | E7: 116.45 | F7: 116.01205 | G7: 1552030 | H7: =(G7-'Descriptive Stats'!$B$55)/('Descriptive Stats'!$B$56-'Descriptive Stats'!$B$55) -> 0.084079131 | I7: =E7/E6 -> 1.0025828 | J7: =I7-1 -> 0.0025828239 | K7: =C7-D7 -> 6.199997 | L7: =(K7-'Descriptive Stats'!$B$60)/('Descriptive Stats'!$B$61-'Descriptive Stats'!$B$60) -> 0.15239479 | M7: =((E7-E6)/E6)*100 -> 0.25828239 | N7: =(M7-'Descriptive Stats'!$B$65)/('Descriptive Stats'!$B$66-'Descriptive Stats'!$B$65) -> 0.39868433 | O7: =((G7-G6)/G6)*100 -> 16.448305 | Q7: 0 | U7: 21/03/24 | V7: 7.05 | W7: 7.08 | X7: 7.08 | Y7: 7.048
A8: 44298 | B8: 113.5 | C8: 114 | D8: 102 | E8: 104.4 | F8: 104.00737 | G8: 1241621 | H8: =(G8-'Descriptive Stats'!$B$55)/('Descriptive Stats'!$B$56-'Descriptive Stats'!$B$55) -> 0.066617794 | I8: =E8/E7 -> 0.89652215 | J8: =I8-1 -> -0.10347785 | K8: =C8-D8 -> 12 | L8: =(K8-'Descriptive Stats'!$B$60)/('Descriptive Stats'!$B$61-'Descriptive Stats'!$B$60) -> 0.32075483 | M8: =((E8-E7)/E7)*100 -> -10.347785 | N8: =(M8-'Descriptive Stats'!$B$65)/('Descriptive Stats'!$B$66-'Descriptive Stats'!$B$65) -> 0 | O8: =((G8-G7)/G7)*100 -> -20.000193 | Q8: 0 | U8: 20/03/24 | V8: 7.097 | W8: 7.101 | X8: 7.103 | Y8: 7.089
A9: 44299 | B9: 105.05 | C9: 111 | D9: 105.05 | E9: 109.2 | F9: 108.78931 | G9: 1016289 | H9: =(G9-'Descriptive Stats'!$B$55)/('Descriptive Stats'!$B$56-'Descriptive Stats'!$B$55) -> 0.053942266 | I9: =E9/E8 -> 1.045977 | J9: =I9-1 -> 0.045976963 | K9: =C9-D9 -> 5.949997 | L9: =(K9-'Descriptive Stats'!$B$60)/('Descriptive Stats'!$B$61-'Descriptive Stats'!$B$60) -> 0.14513789 | M9: =((E9-E8)/E8)*100 -> 4.5976963 | N9: =(M9-'Descriptive Stats'!$B$65)/('Descriptive Stats'!$B$66-'Descriptive Stats'!$B$65) -> 0.56180383 | O9: =((G9-G8)/G8)*100 -> -18.148211 | Q9: 0 | U9: 19/03/24 | V9: 7.095 | W9: 7.096 | X9: 7.1 | Y9: 7.081
A10: 44301 | B10: 108.15 | C10: 109.95 | D10: 104.7 | E10: 107.1 | F10: 106.69721 | G10: 388528 | H10: =(G10-'Descriptive Stats'!$B$55)/('Descriptive Stats'!$B$56-'Descriptive Stats'!$B$55) -> 0.01862903 | I10: =E10/E9 -> 0.98076924 | J10: =I10-1 -> -0.019230761 | K10: =C10-D10 -> 5.25 | L10: =(K10-'Descriptive Stats'!$B$60)/('Descriptive Stats'!$B$61-'Descriptive Stats'!$B$60) -> 0.12481868 | M10: =((E10-E9)/E9)*100 -> -1.9230761 | N10: =(M10-'Descriptive Stats'!$B$65)/('Descriptive Stats'!$B$66-'Descriptive Stats'!$B$65) -> 0.3166866 | O10: =((G10-G9)/G9)*100 -> -61.76993 | Q10: 0 | U10: 18/03/24 | V10: 7.087 | W10: 7.08 | X10: 7.088 | Y10: 7.075
A11: 44302 | B11: 107.9 | C11: 114.7 | D11: 106.8 | E11: 112.3 | F11: 111.87766 | G11: 1006186 | H11: =(G11-'Descriptive Stats'!$B$55)/('Descriptive Stats'!$B$56-'Descriptive Stats'!$B$55) -> 0.053373946 | I11: =E11/E10 -> 1.0485528 | J11: =I11-1 -> 0.048552802 | K11: =C11-D11 -> 7.899994 | L11: =(K11-'Descriptive Stats'!$B$60)/('Descriptive Stats'!$B$61-'Descriptive Stats'!$B$60) -> 0.20174159 | M11: =((E11-E10)/E10)*100 -> 4.8552802 | N11: =(M11-'Descriptive Stats'!$B$65)/('Descriptive Stats'!$B$66-'Descriptive Stats'!$B$65) -> 0.57148646 | O11: =((G11-G10)/G10)*100 -> 158.97387 | Q11: 0 | U11: 15/03/24 | V11: 7.062 | W11: 7.06 | X11: 7.064 | Y11: 7.051
A12: 44305 | B12: 108.9 | C12: 110.1 | D12: 106.2 | E12: 108.55 | F12: 108.14177 | G12: 448582 | H12: =(G12-'Descriptive Stats'!$B$55)/('Descriptive Stats'!$B$56-'Descriptive Stats'!$B$55) -> 0.022007228 | I12: =E12/E11 -> 0.9666073 | J12: =I12-1 -> -0.033392697 | K12: =C12-D12 -> 3.900001 | L12: =(K12-'Descriptive Stats'!$B$60)/('Descriptive Stats'!$B$61-'Descriptive Stats'!$B$60) -> 0.085631473 | M12: =((E12-E11)/E11)*100 -> -3.3392697 | N12: =(M12-'Descriptive Stats'!$B$65)/('Descriptive Stats'!$B$66-'Descriptive Stats'!$B$65) -> 0.26345158 | O12: =((G12-G11)/G11)*100 -> -55.417587 | Q12: 0 | R12: Smoothing factor for 12 | S12: =2/13 -> 0.15384615 | U12: 14/03/24 | V12: 7.041 | W12: 7.046 | X12: 7.048 | Y12: 7.038
A13: 44306 | B13: 109.15 | C13: 111.7 | D13: 105.9 | E13: 106.9 | F13: 106.49797 | G13: 279311 | H13: =(G13-'Descriptive Stats'!$B$55)/('Descriptive Stats'!$B$56-'Descriptive Stats'!$B$55) -> 0.012485281 | I13: =E13/E12 -> 0.98479962 | J13: =I13-1 -> -0.015200377 | K13: =C13-D13 -> 5.799995 | L13: =(K13-'Descriptive Stats'!$B$60)/('Descriptive Stats'!$B$61-'Descriptive Stats'!$B$60) -> 0.1407837 | M13: =((E13-E12)/E12)*100 -> -1.5200377 | N13: =(M13-'Descriptive Stats'!$B$65)/('Descriptive Stats'!$B$66-'Descriptive Stats'!$B$65) -> 0.3318369 | O13: =((G13-G12)/G12)*100 -> -37.734684 | Q13: 0 | R13: Smoothing factor for 26 | S13: =2/27 -> 0.074074074 | U13: 13/03/24 | V13: 7.039 | W13: 7.043 | X13: 7.043 | Y13: 7.03
A14: 44308 | B14: 106.9 | C14: 109.75 | D14: 105.1 | E14: 106.8 | F14: 106.39835 | G14: 319736 | H14: =(G14-'Descriptive Stats'!$B$55)/('Descriptive Stats'!$B$56-'Descriptive Stats'!$B$55) -> 0.014759296 | I14: =E14/E13 -> 0.99906456 | J14: =I14-1 -> -0.00093544432 | K14: =C14-D14 -> 4.650002 | L14: =(K14-'Descriptive Stats'!$B$60)/('Descriptive Stats'!$B$61-'Descriptive Stats'!$B$60) -> 0.10740219 | M14: =((E14-E13)/E13)*100 -> -0.093544432 | N14: =(M14-'Descriptive Stats'!$B$65)/('Descriptive Stats'!$B$66-'Descriptive Stats'!$B$65) -> 0.38545909 | O14: =((G14-G13)/G13)*100 -> 14.473114 | Q14: 0 | R14: Smoothing factor 9 | S14: =2/10 -> 0.2 | U14: 45629 | V14: 7.026 | W14: 7.025 | X14: 7.029 | Y14: 7.015
A15: 44309 | B15: 107.45 | C15: 115.5 | D15: 106.9 | E15: 111.75 | F15: 111.32973 | G15: 1058052 | H15: =(G15-'Descriptive Stats'!$B$55)/('Descriptive Stats'!$B$56-'Descriptive Stats'!$B$55) -> 0.056291547 | I15: =E15/E14 -> 1.0463483 | J15: =I15-1 -> 0.046348285 | K15: =C15-D15 -> 8.599998 | L15: =(K15-'Descriptive Stats'!$B$60)/('Descriptive Stats'!$B$61-'Descriptive Stats'!$B$60) -> 0.22206101 | M15: =((E15-E14)/E14)*100 -> 4.6348285 | N15: =(M15-'Descriptive Stats'!$B$65)/('Descriptive Stats'!$B$66-'Descriptive Stats'!$B$65) -> 0.56319964 | O15: =((G15-G14)/G14)*100 -> 230.91425 | Q15: 0 | U15: 45599 | V15: 7.014 | W15: 7.025 | X15: 7.025 | Y15: 7.006
A16: 44312 | B16: 112.45 | C16: 114.9 | D16: 111.05 | E16: 114.3 | F16: 113.87014 | G16: 525753 | H16: =(G16-'Descriptive Stats'!$B$55)/('Descriptive Stats'!$B$56-'Descriptive Stats'!$B$55) -> 0.026348304 | I16: =E16/E15 -> 1.0228188 | J16: =I16-1 -> 0.022818819 | K16: =C16-D16 -> 3.849999 | L16: =(K16-'Descriptive Stats'!$B$60)/('Descriptive Stats'!$B$61-'Descriptive Stats'!$B$60) -> 0.084180036 | M16: =((E16-E15)/E15)*100 -> 2.2818819 | N16: =(M16-'Descriptive Stats'!$B$65)/('Descriptive Stats'!$B$66-'Descriptive Stats'!$B$65) -> 0.47475187 | O16: =((G16-G15)/G15)*100 -> -50.309342 | Q16: 0 | U16: 45476 | V16: 7.031 | W16: 7.054 | X16: 7.054 | Y16: 7.026
A17: 44313 | B17: 115 | C17: 115.65 | D17: 111 | E17: 111.9 | F17: 111.47916 | G17: 425358 | H17: =(G17-'Descriptive Stats'!$B$55)/('Descriptive Stats'!$B$56-'Descriptive Stats'!$B$55) -> 0.020700816 | I17: =E17/E16 -> 0.97900262 | J17: =I17-1 -> -0.020997384 | K17: =C17-D17 -> 4.650002 | L17: =(K17-'Descriptive Stats'!$B$60)/('Descriptive Stats'!$B$61-'Descriptive Stats'!$B$60) -> 0.10740219 | M17: =((E17-E16)/E16)*100 -> -2.0997384 | N17: =(M17-'Descriptive Stats'!$B$65)/('Descriptive Stats'!$B$66-'Descriptive Stats'!$B$65) -> 0.31004583 | O17: =((G17-G16)/G16)*100 -> -19.095469 | Q17: 0 | U17: 45446 | V17: 7.054 | W17: 7.053 | X17: 7.057 | Y17: 7.048
A18: 44314 | B18: 113.3 | C18: 115.6 | D18: 112.3 | E18: 114.15 | F18: 113.7207 | G18: 576458 | H18: =(G18-'Descriptive Stats'!$B$55)/('Descriptive Stats'!$B$56-'Descriptive Stats'!$B$55) -> 0.029200595 | I18: =E18/E17 -> 1.0201072 | J18: =I18-1 -> 0.020107238 | K18: =C18-D18 -> 3.299995 | L18: =(K18-'Descriptive Stats'!$B$60)/('Descriptive Stats'!$B$61-'Descriptive Stats'!$B$60) -> 0.068214752 | M18: =((E18-E17)/E17)*100 -> 2.0107238 | N18: =(M18-'Descriptive Stats'!$B$65)/('Descriptive Stats'!$B$66-'Descriptive Stats'!$B$65) -> 0.46455898 | O18: =((G18-G17)/G17)*100 -> 35.523018 | Q18: 0 | U18: 45415 | V18: 7.057 | W18: 7.066 | X18: 7.066 | Y18: 7.053
A19: 44315 | B19: 115 | C19: 115.45 | D19: 110.9 | E19: 112.05 | F19: 111.6286 | G19: 409072 | H19: =(G19-'Descriptive Stats'!$B$55)/('Descriptive Stats'!$B$56-'Descriptive Stats'!$B$55) -> 0.019784685 | I19: =E19/E18 -> 0.98160316 | J19: =I19-1 -> -0.018396837 | K19: =C19-D19 -> 4.549995 | L19: =(K19-'Descriptive Stats'!$B$60)/('Descriptive Stats'!$B$61-'Descriptive Stats'!$B$60) -> 0.10449923 | M19: =((E19-E18)/E18)*100 -> -1.8396837 | N19: =(M19-'Descriptive Stats'!$B$65)/('Descriptive Stats'!$B$66-'Descriptive Stats'!$B$65) -> 0.31982134 | O19: =((G19-G18)/G18)*100 -> -29.036981 | Q19: 0 | U19: 45385 | V19: 7.06 | W19: 7.051 | X19: 7.062 | Y19: 7.047
A20: 44316 | B20: 111 | C20: 116.6 | D20: 111 | E20: 111.7 | F20: 111.27992 | G20: 707041 | H20: =(G20-'Descriptive Stats'!$B$55)/('Descriptive Stats'!$B$56-'Descriptive Stats'!$B$55) -> 0.036546239 | I20: =E20/E19 -> 0.99687634 | J20: =I20-1 -> -0.003123659 | K20: =C20-D20 -> 5.599998 | L20: =(K20-'Descriptive Stats'!$B$60)/('Descriptive Stats'!$B$61-'Descriptive Stats'!$B$60) -> 0.13497827 | M20: =((E20-E19)/E19)*100 -> -0.3123659 | N20: =(M20-'Descriptive Stats'!$B$65)/('Descriptive Stats'!$B$66-'Descriptive Stats'!$B$65) -> 0.37723354 | O20: =((G20-G19)/G19)*100 -> 72.840233 | Q20: 0 | U20: 45294 | V20: 7.06 | W20: 7.062 | X20: 7.082 | Y20: 7.057
A21: 44319 | B21: 111.05 | C21: 115.5 | D21: 111.05 | E21: 113.95 | F21: 113.52145 | G21: 404637 | H21: =(G21-'Descriptive Stats'!$B$55)/('Descriptive Stats'!$B$56-'Descriptive Stats'!$B$55) -> 0.019535204 | I21: =E21/E20 -> 1.0201432 | J21: =I21-1 -> 0.020143241 | K21: =C21-D21 -> 4.449997 | L21: =(K21-'Descriptive Stats'!$B$60)/('Descriptive Stats'!$B$61-'Descriptive Stats'!$B$60) -> 0.10159653 | M21: =((E21-E20)/E20)*100 -> 2.0143241 | N21: =(M21-'Descriptive Stats'!$B$65)/('Descriptive Stats'!$B$66-'Descriptive Stats'!$B$65) -> 0.46469432 | O21: =((G21-G20)/G20)*100 -> -42.770363 | Q21: 0 | U21: 29/02/24 | V21: 7.078 | W21: 7.059 | X21: 7.082 | Y21: 7.057
A22: 44320 | B22: 114.5 | C22: 118.6 | D22: 114.05 | E22: 115.35 | F22: 114.91619 | G22: 1164324 | H22: =(G22-'Descriptive Stats'!$B$55)/('Descriptive Stats'!$B$56-'Descriptive Stats'!$B$55) -> 0.062269631 | I22: =E22/E21 -> 1.0122861 | J22: =I22-1 -> 0.012286099 | K22: =C22-D22 -> 4.549995 | L22: =(K22-'Descriptive Stats'!$B$60)/('Descriptive Stats'!$B$61-'Descriptive Stats'!$B$60) -> 0.10449923 | M22: =((E22-E21)/E21)*100 -> 1.2286099 | N22: =(M22-'Descriptive Stats'!$B$65)/('Descriptive Stats'!$B$66-'Descriptive Stats'!$B$65) -> 0.43515915 | O22: =((G22-G21)/G21)*100 -> 187.74531 | Q22: 0 | U22: 28/02/24 | V22: 7.065 | W22: 7.076 | X22: 7.076 | Y22: 7.06
A23: 44321 | B23: 115.7 | C23: 137 | D23: 115.55 | E23: 134.10001 | F23: 133.59569 | G23: 9274147 | H23: =(G23-'Descriptive Stats'!$B$55)/('Descriptive Stats'!$B$56-'Descriptive Stats'!$B$55) -> 0.51846888 | I23: =E23/E22 -> 1.1625488 | J23: =I23-1 -> 0.16254884 | K23: =C23-D23 -> 21.449997 | L23: =(K23-'Descriptive Stats'!$B$60)/('Descriptive Stats'!$B$61-'Descriptive Stats'!$B$60) -> 0.59506536 | M23: =((E23-E22)/E22)*100 -> 16.254884 | N23: =(M23-'Descriptive Stats'!$B$65)/('Descriptive Stats'!$B$66-'Descriptive Stats'!$B$65) -> 1 | O23: =((G23-G22)/G22)*100 -> 696.52631 | Q23: 0 | U23: 27/02/24 | V23: 7.068 | W23: 7.074 | X23: 7.074 | Y23: 7.061
A24: 44322 | B24: 137.5 | C24: 143.8 | D24: 132.2 | E24: 138.89999 | F24: 138.37761 | G24: 6033249 | H24: =(G24-'Descriptive Stats'!$B$55)/('Descriptive Stats'!$B$56-'Descriptive Stats'!$B$55) -> 0.33615969 | I24: =E24/E23 -> 1.0357941 | J24: =I24-1 -> 0.035794092 | K24: =C24-D24 -> 11.600006 | L24: =(K24-'Descriptive Stats'!$B$60)/('Descriptive Stats'!$B$61-'Descriptive Stats'!$B$60) -> 0.30914397 | M24: =((E24-E23)/E23)*100 -> 3.5794092 | N24: =(M24-'Descriptive Stats'!$B$65)/('Descriptive Stats'!$B$66-'Descriptive Stats'!$B$65) -> 0.5235262 | O24: =((G24-G23)/G23)*100 -> -34.94551 | Q24: 0 | U24: 26/02/24 | V24: 7.063 | W24: 7.055 | X24: 7.066 | Y24: 7.046
A25: 44323 | B25: 139.85001 | C25: 141.75 | D25: 134.60001 | E25: 135.5 | F25: 134.9904 | G25: 1282935 | H25: =(G25-'Descriptive Stats'!$B$55)/('Descriptive Stats'!$B$56-'Descriptive Stats'!$B$55) -> 0.068941817 | I25: =E25/E24 -> 0.975522 | J25: =I25-1 -> -0.024478 | K25: =C25-D25 -> 7.149994 | L25: =(K25-'Descriptive Stats'!$B$60)/('Descriptive Stats'!$B$61-'Descriptive Stats'!$B$60) -> 0.1799709 | M25: =((E25-E24)/E24)*100 -> -2.4478 | N25: =(M25-'Descriptive Stats'!$B$65)/('Descriptive Stats'!$B$66-'Descriptive Stats'!$B$65) -> 0.29696212 | O25: =((G25-G24)/G24)*100 -> -78.735587 | Q25: 0 | U25: 23/02/24 | V25: 7.077 | W25: 7.074 | X25: 7.081 | Y25: 7.062
A26: 44326 | B26: 139 | C26: 140.5 | D26: 135.60001 | E26: 137.75 | F26: 137.23195 | G26: 1021520 | H26: =(G26-'Descriptive Stats'!$B$55)/('Descriptive Stats'!$B$56-'Descriptive Stats'!$B$55) -> 0.054236524 | I26: =E26/E25 -> 1.0166052 | J26: =I26-1 -> 0.016605166 | K26: =C26-D26 -> 4.899994 | L26: =(K26-'Descriptive Stats'!$B$60)/('Descriptive Stats'!$B$61-'Descriptive Stats'!$B$60) -> 0.11465885 | M26: =((E26-E25)/E25)*100 -> 1.6605166 | N26: =(M26-'Descriptive Stats'!$B$65)/('Descriptive Stats'!$B$66-'Descriptive Stats'!$B$65) -> 0.45139462 | O26: =((G26-G25)/G25)*100 -> -20.376325 | Q26: 0 | U26: 22/02/24 | V26: 7.062 | W26: 7.062 | X26: 7.076 | Y26: 7.045
A27: 44327 | B27: 135 | C27: 150.60001 | D27: 132.60001 | E27: 146.60001 | F27: 146.04868 | G27: 3087135 | H27: =(G27-'Descriptive Stats'!$B$55)/('Descriptive Stats'!$B$56-'Descriptive Stats'!$B$55) -> 0.1704329 | I27: =E27/E26 -> 1.0642469 | J27: =I27-1 -> 0.064246868 | K27: =C27-D27 -> 18 | L27: =(K27-'Descriptive Stats'!$B$60)/('Descriptive Stats'!$B$61-'Descriptive Stats'!$B$60) -> 0.4949203 | M27: =((E27-E26)/E26)*100 -> 6.4246868 | N27: =(M27-'Descriptive Stats'!$B$65)/('Descriptive Stats'!$B$66-'Descriptive Stats'!$B$65) -> 0.63048079 | O27: =((G27-G26)/G26)*100 -> 202.20994 | Q27: 0 | U27: 21/02/24 | V27: 7.045 | W27: 7.065 | X27: 7.065 | Y27: 7.038
A28: 44328 | B28: 146.5 | C28: 157.8 | D28: 144 | E28: 149.64999 | F28: 149.08719 | G28: 2302867 | H28: =(G28-'Descriptive Stats'!$B$55)/('Descriptive Stats'!$B$56-'Descriptive Stats'!$B$55) -> 0.12631572 | I28: =E28/E27 -> 1.0208048 | J28: =I28-1 -> 0.020804829 | K28: =C28-D28 -> 13.800003 | L28: =(K28-'Descriptive Stats'!$B$60)/('Descriptive Stats'!$B$61-'Descriptive Stats'!$B$60) -> 0.37300456 | M28: =((E28-E27)/E27)*100 -> 2.0804829 | N28: =(M28-'Descriptive Stats'!$B$65)/('Descriptive Stats'!$B$66-'Descriptive Stats'!$B$65) -> 0.46718124 | O28: =((G28-G27)/G27)*100 -> -25.404396 | Q28: 0 | U28: 20/02/24 | V28: 7.062 | W28: 7.118 | X28: 7.118 | Y28: 7.06
A29: 44330 | B29: 151.60001 | C29: 153 | D29: 141.05 | E29: 145.75 | F29: 145.20186 | G29: 1079044 | H29: =(G29-'Descriptive Stats'!$B$55)/('Descriptive Stats'!$B$56-'Descriptive Stats'!$B$55) -> 0.057472403 | I29: =E29/E28 -> 0.97393923 | J29: =I29-1 -> -0.02606077 | K29: =C29-D29 -> 11.949997 | L29: =(K29-'Descriptive Stats'!$B$60)/('Descriptive Stats'!$B$61-'Descriptive Stats'!$B$60) -> 0.31930337 | M29: =((E29-E28)/E28)*100 -> -2.6060769 | N29: =(M29-'Descriptive Stats'!$B$65)/('Descriptive Stats'!$B$66-'Descriptive Stats'!$B$65) -> 0.29101245 | O29: =((G29-G28)/G28)*100 -> -53.143451 | Q29: 0 | U29: 16/02/24 | V29: 7.099 | W29: 7.097 | X29: 7.103 | Y29: 7.075
A30: 44333 | B30: 148.7 | C30: 151 | D30: 146.05 | E30: 146.75 | F30: 146.1981 | G30: 721676 | H30: =(G30-'Descriptive Stats'!$B$55)/('Descriptive Stats'!$B$56-'Descriptive Stats'!$B$55) -> 0.037369497 | I30: =E30/E29 -> 1.0068611 | J30: =I30-1 -> 0.0068610635 | K30: =C30-D30 -> 4.949997 | L30: =(K30-'Descriptive Stats'!$B$60)/('Descriptive Stats'!$B$61-'Descriptive Stats'!$B$60) -> 0.11611031 | M30: =((E30-E29)/E29)*100 -> 0.68610635 | N30: =(M30-'Descriptive Stats'!$B$65)/('Descriptive Stats'!$B$66-'Descriptive Stats'!$B$65) -> 0.41476633 | O30: =((G30-G29)/G29)*100 -> -33.118946 | Q30: 0 | U30: 15/02/24 | V30: 7.085 | W30: 7.104 | X30: 7.104 | Y30: 7.079
A31: 44334 | B31: 147.95 | C31: 149.05 | D31: 143 | E31: 143.60001 | F31: 143.05995 | G31: 426155 | H31: =(G31-'Descriptive Stats'!$B$55)/('Descriptive Stats'!$B$56-'Descriptive Stats'!$B$55) -> 0.020745649 | I31: =E31/E30 -> 0.97853496 | J31: =I31-1 -> -0.021465036 | K31: =C31-D31 -> 6.050003 | L31: =(K31-'Descriptive Stats'!$B$60)/('Descriptive Stats'!$B$61-'Descriptive Stats'!$B$60) -> 0.14804083 | M31: =((E31-E30)/E30)*100 -> -2.1465036 | N31: =(M31-'Descriptive Stats'!$B$65)/('Descriptive Stats'!$B$66-'Descriptive Stats'!$B$65) -> 0.30828791 | O31: =((G31-G30)/G30)*100 -> -40.949263 | Q31: 0 | U31: 14/02/24 | V31: 7.114 | W31: 7.136 | X31: 7.14 | Y31: 7.11
A32: 44335 | B32: 144.25 | C32: 147.85001 | D32: 143.10001 | E32: 144.14999 | F32: 143.60788 | G32: 405679 | H32: =(G32-'Descriptive Stats'!$B$55)/('Descriptive Stats'!$B$56-'Descriptive Stats'!$B$55) -> 0.01959382 | I32: =E32/E31 -> 1.00383 | J32: =I32-1 -> 0.0038299998 | K32: =C32-D32 -> 4.75 | L32: =(K32-'Descriptive Stats'!$B$60)/('Descriptive Stats'!$B$61-'Descriptive Stats'!$B$60) -> 0.11030489 | M32: =((E32-E31)/E31)*100 -> 0.38299998 | N32: =(M32-'Descriptive Stats'!$B$65)/('Descriptive Stats'!$B$66-'Descriptive Stats'!$B$65) -> 0.40337249 | O32: =((G32-G31)/G31)*100 -> -4.8048245 | Q32: 0 | U32: 13/02/24 | V32: 7.097 | W32: 7.105 | X32: 7.109 | Y32: 7.096
A33: 44336 | B33: 146.60001 | C33: 146.60001 | D33: 140.5 | E33: 140.89999 | F33: 140.3701 | G33: 378596 | H33: =(G33-'Descriptive Stats'!$B$55)/('Descriptive Stats'!$B$56-'Descriptive Stats'!$B$55) -> 0.018070328 | I33: =E33/E32 -> 0.97745404 | J33: =I33-1 -> -0.02254596 | K33: =C33-D33 -> 6.100006 | L33: =(K33-'Descriptive Stats'!$B$60)/('Descriptive Stats'!$B$61-'Descriptive Stats'!$B$60) -> 0.14949229 | M33: =((E33-E32)/E32)*100 -> -2.254596 | N33: =(M33-'Descriptive Stats'!$B$65)/('Descriptive Stats'!$B$66-'Descriptive Stats'!$B$65) -> 0.3042247 | O33: =((G33-G32)/G32)*100 -> -6.6759679 | Q33: 0 | U33: 45628 | V33: 7.097 | W33: 7.12 | X33: 7.12 | Y33: 7.09
A34: 44337 | B34: 141 | C34: 144.7 | D34: 140.10001 | E34: 140.55 | F34: 140.02142 | G34: 390552 | H34: =(G34-'Descriptive Stats'!$B$55)/('Descriptive Stats'!$B$56-'Descriptive Stats'!$B$55) -> 0.018742885 | I34: =E34/E33 -> 0.99751603 | J34: =I34-1 -> -0.0024839675 | K34: =C34-D34 -> 4.599991 | L34: =(K34-'Descriptive Stats'!$B$60)/('Descriptive Stats'!$B$61-'Descriptive Stats'!$B$60) -> 0.10595049 | M34: =((E34-E33)/E33)*100 -> -0.24839675 | N34: =(M34-'Descriptive Stats'!$B$65)/('Descriptive Stats'!$B$66-'Descriptive Stats'!$B$65) -> 0.37963816 | O34: =((G34-G33)/G33)*100 -> 3.1579837 | Q34: 0 | U34: 45537 | V34: 7.114 | W34: 7.091 | X34: 7.118 | Y34: 7.075
A35: 44340 | B35: 141 | C35: 143.10001 | D35: 139.45 | E35: 141.45 | F35: 140.91803 | G35: 329083 | H35: =(G35-'Descriptive Stats'!$B$55)/('Descriptive Stats'!$B$56-'Descriptive Stats'!$B$55) -> 0.01528509 | I35: =E35/E34 -> 1.0064034 | J35: =I35-1 -> 0.0064033723 | K35: =C35-D35 -> 3.650009 | L35: =(K35-'Descriptive Stats'!$B$60)/('Descriptive Stats'!$B$61-'Descriptive Stats'!$B$60) -> 0.078374811 | M35: =((E35-E34)/E34)*100 -> 0.64033723 | N35: =(M35-'Descriptive Stats'!$B$65)/('Descriptive Stats'!$B$66-'Descriptive Stats'!$B$65) -> 0.41304586 | O35: =((G35-G34)/G34)*100 -> -15.739005 | Q35: 0 | U35: 45506 | V35: 7.082 | W35: 7.073 | X35: 7.092 | Y35: 7.048
A36: 44341 | B36: 141.45 | C36: 147.75 | D36: 141.3 | E36: 145.39999 | F36: 144.85316 | G36: 719677 | H36: =(G36-'Descriptive Stats'!$B$55)/('Descriptive Stats'!$B$56-'Descriptive Stats'!$B$55) -> 0.037257048 | I36: =E36/E35 -> 1.027925 | J36: =I36-1 -> 0.027925041 | K36: =C36-D36 -> 6.449997 | L36: =(K36-'Descriptive Stats'!$B$60)/('Descriptive Stats'!$B$61-'Descriptive Stats'!$B$60) -> 0.15965168 | M36: =((E36-E35)/E35)*100 -> 2.7925041 | N36: =(M36-'Descriptive Stats'!$B$65)/('Descriptive Stats'!$B$66-'Descriptive Stats'!$B$65) -> 0.49394627 | O36: =((G36-G35)/G35)*100 -> 118.69164 | Q36: 0 | U36: 45475 | V36: 7.074 | W36: 7.075 | X36: 7.078 | Y36: 7.064
A37: 44342 | B37: 146 | C37: 146.7 | D37: 139.75 | E37: 140.60001 | F37: 140.07123 | G37: 474210 | H37: =(G37-'Descriptive Stats'!$B$55)/('Descriptive Stats'!$B$56-'Descriptive Stats'!$B$55) -> 0.023448872 | I37: =E37/E36 -> 0.9669877 | J37: =I37-1 -> -0.033012298 | K37: =C37-D37 -> 6.949997 | L37: =(K37-'Descriptive Stats'!$B$60)/('Descriptive Stats'!$B$61-'Descriptive Stats'!$B$60) -> 0.17416547 | M37: =((E37-E36)/E36)*100 -> -3.3012298 | N37: =(M37-'Descriptive Stats'!$B$65)/('Descriptive Stats'!$B$66-'Descriptive Stats'!$B$65) -> 0.26488151 | O37: =((G37-G36)/G36)*100 -> -34.10794 | Q37: 0 | U37: 45445 | V37: 7.092 | W37: 7.096 | X37: 7.096 | Y37: 7.07
A38: 44343 | B38: 141.7 | C38: 143.5 | D38: 140.7 | E38: 141.14999 | F38: 140.61916 | G38: 270275 | H38: =(G38-'Descriptive Stats'!$B$55)/('Descriptive Stats'!$B$56-'Descriptive Stats'!$B$55) -> 0.011976982 | I38: =E38/E37 -> 1.0039117 | J38: =I38-1 -> 0.003911721 | K38: =C38-D38 -> 2.800003 | L38: =(K38-'Descriptive Stats'!$B$60)/('Descriptive Stats'!$B$61-'Descriptive Stats'!$B$60) -> 0.053701195 | M38: =((E38-E37)/E37)*100 -> 0.3911721 | N38: =(M38-'Descriptive Stats'!$B$65)/('Descriptive Stats'!$B$66-'Descriptive Stats'!$B$65) -> 0.40367969 | O38: =((G38-G37)/G37)*100 -> -43.005209 | Q38: 0 | U38: 45414 | V38: 7.091 | W38: 7.092 | X38: 7.096 | Y38: 7.071
A39: 44344 | B39: 142.2 | C39: 143.39999 | D39: 137.10001 | E39: 137.89999 | F39: 137.38138 | G39: 404747 | H39: =(G39-'Descriptive Stats'!$B$55)/('Descriptive Stats'!$B$56-'Descriptive Stats'!$B$55) -> 0.019541392 | I39: =E39/E38 -> 0.97697485 | J39: =I39-1 -> -0.023025152 | K39: =C39-D39 -> 6.299988 | L39: =(K39-'Descriptive Stats'!$B$60)/('Descriptive Stats'!$B$61-'Descriptive Stats'!$B$60) -> 0.15529728 | M39: =((E39-E38)/E38)*100 -> -2.3025152 | N39: =(M39-'Descriptive Stats'!$B$65)/('Descriptive Stats'!$B$66-'Descriptive Stats'!$B$65) -> 0.30242341 | O39: =((G39-G38)/G38)*100 -> 49.753769 | Q39: 0 | U39: 45324 | V39: 7.05 | W39: 7.054 | X39: 7.058 | Y39: 7.021
A40: 44347 | B40: 138.05 | C40: 139.45 | D40: 134 | E40: 135.10001 | F40: 134.59192 | G40: 448153 | H40: =(G40-'Descriptive Stats'!$B$55)/('Descriptive Stats'!$B$56-'Descriptive Stats'!$B$55) -> 0.021983096 | I40: =E40/E39 -> 0.97969552 | J40: =I40-1 -> -0.020304482 | K40: =C40-D40 -> 5.449997 | L40: =(K40-'Descriptive Stats'!$B$60)/('Descriptive Stats'!$B$61-'Descriptive Stats'!$B$60) -> 0.1306241 | M40: =((E40-E39)/E39)*100 -> -2.0304482 | N40: =(M40-'Descriptive Stats'!$B$65)/('Descriptive Stats'!$B$66-'Descriptive Stats'!$B$65) -> 0.31265046 | O40: =((G40-G39)/G39)*100 -> 10.72423 | Q40: 0 | U40: 45293 | V40: 7.064 | W40: 7.129 | X40: 7.135 | Y40: 7.039
...

Sheet Historical Data Monthly
A1: Date | B1: Open | C1: High | D1: Low | E1: Close | F1: Adj Close | G1: Volume | H1: HPR | I1: HPY
A2: 44287 | B2: 106.5 | C2: 121.25 | D2: 102 | E2: 111.7 | F2: 111.27992 | G2: 18016486
A3: 44317 | B3: 111.05 | C3: 157.8 | D3: 111.05 | E3: 135.10001 | F3: 134.59192 | G3: 30618661 | H3: =E3/E2 -> 1.2094898 | I3: =H3-1 -> 0.20948979
A4: 44348 | B4: 137.5 | C4: 150.5 | D4: 133.05 | E4: 136.60001 | F4: 136.08627 | G4: 19306625 | H4: =E4/E3 -> 1.0111029 | I4: =H4-1 -> 0.011102886
A5: 44378 | B5: 136.7 | C5: 148.60001 | D5: 130.5 | E5: 138.55 | F5: 138.02895 | G5: 16815794 | H5: =E5/E4 -> 1.0142752 | I5: =H5-1 -> 0.014275234
A6: 44409 | B6: 141.95 | C6: 142 | D6: 112.05 | E6: 132.89999 | F6: 132.40018 | G6: 11505147 | H6: =E6/E5 -> 0.95922043 | I6: =H6-1 -> -0.040779566
A7: 44440 | B7: 134 | C7: 140 | D7: 120.75 | E7: 125.95 | F7: 125.47633 | G7: 12245363 | H7: =E7/E6 -> 0.94770506 | I7: =H7-1 -> -0.052294938
A8: 44470 | B8: 125.45 | C8: 149.7 | D8: 125 | E8: 134.35001 | F8: 134.35001 | G8: 14081301 | H8: =E8/E7 -> 1.0666932 | I8: =H8-1 -> 0.066693205
A9: 44501 | B9: 134.95 | C9: 159.89999 | D9: 121.15 | E9: 122.75 | F9: 122.75 | G9: 17825231 | H9: =E9/E8 -> 0.91365831 | I9: =H9-1 -> -0.086341686
A10: 44531 | B10: 123.5 | C10: 126.1 | D10: 102.1 | E10: 111.8 | F10: 111.8 | G10: 12946094 | H10: =E10/E9 -> 0.91079432 | I10: =H10-1 -> -0.089205678
A11: 44562 | B11: 112 | C11: 125.45 | D11: 109.5 | E11: 109.95 | F11: 109.95 | G11: 10311626 | H11: =E11/E10 -> 0.98345254 | I11: =H11-1 -> -0.016547459
A12: 44593 | B12: 110.05 | C12: 119.2 | D12: 95.099998 | E12: 100.5 | F12: 100.5 | G12: 6988108 | H12: =E12/E11 -> 0.91405187 | I12: =H12-1 -> -0.085948133
A13: 44621 | B13: 100.5 | C13: 105.75 | D13: 95 | E13: 96.75 | F13: 96.75 | G13: 9704704 | H13: =E13/E12 -> 0.96268657 | I13: =H13-1 -> -0.037313433
A14: 44652 | B14: 96.599998 | C14: 112.4 | D14: 96.599998 | E14: 100.95 | F14: 100.95 | G14: 7983568 | H14: =E14/E13 -> 1.0434108 | I14: =H14-1 -> 0.043410822
... A37: 45352 | B37: 245.55 | C37: 250.8 | D37: 188.39999 | E37: 207.89999 | F37: 207.89999 | G37: 23064241 | H37: =E37/E36 -> 0.85555553 | I37: =H37-1 -> -0.14444447

Sheet NIFTY 50 
A1: NIFTY 50 DAILY | L1: NIFTY 50 MONTHLY
A2: Date | B2: Open | C2: High | D2: Low | E2: Close | F2: Adj Close | G2: Volume | H2: HPR | I2: HPY | J2: CHG % | L2: Date | M2: Open | N2: High | O2: Low | P2: Close | Q2: Adj Close | R2: Volume | S2: HPR | T2: HPY
A3: 44287 | B3: 14798.4 | C3: 14883.2 | D3: 14692.45 | E3: 14867.35 | F3: 14867.35 | G3: 445000 | L3: 44287 | M3: 14798.4 | N3: 15044.35 | O3: 14151.4 | P3: 14631.1 | Q3: 14631.1 | R3: 9344700
A4: 44291 | B4: 14837.7 | C4: 14849.85 | D4: 14459.5 | E4: 14637.8 | F4: 14637.8 | G4: 509700 | H4: =(E4/E3) -> 0.98456014 | I4: =H4-1 -> -0.01543986 | J4: =((E4-E3)/E3)*100 -> -1.543986 | L4: 44317 | M4: 14481.05 | N4: 15606.35 | O4: 14416.25 | P4: 15582.8 | Q4: 15582.8 | R4: 9859900 | S4: =P4/P3 -> 1.0650464 | T4: =S4-1 -> 0.065046389
A5: 44292 | B5: 14737 | C5: 14779.1 | D5: 14573.9 | E5: 14683.5 | F5: 14683.5 | G5: 475300 | H5: =(E5/E4) -> 1.0031221 | I5: =H5-1 -> 0.0031220672 | J5: =((E5-E4)/E4)*100 -> 0.31220672 | L5: 44348 | M5: 15629.65 | N5: 15915.65 | O5: 15450.9 | P5: 15721.5 | Q5: 15721.5 | R5: 8079100 | S5: =P5/P4 -> 1.0089009 | T5: =S5-1 -> 0.008900852
A6: 44293 | B6: 14716.45 | C6: 14879.8 | D6: 14649.85 | E6: 14819.05 | F6: 14819.05 | G6: 0 | H6: =(E6/E5) -> 1.0092314 | I6: =H6-1 -> 0.009231437 | J6: =((E6-E5)/E5)*100 -> 0.9231437 | L6: 44378 | M6: 15755.05 | N6: 15962.25 | O6: 15513.45 | P6: 15763.05 | Q6: 15763.05 | R6: 5756800 | S6: =P6/P5 -> 1.0026429 | T6: =S6-1 -> 0.0026428652
A7: 44294 | B7: 14875.65 | C7: 14984.15 | D7: 14821.1 | E7: 14873.8 | F7: 14873.8 | G7: 514800 | H7: =(E7/E6) -> 1.0036946 | I7: =H7-1 -> 0.0036945689 | J7: =((E7-E6)/E6)*100 -> 0.36945689 | L7: 44409 | M7: 15874.9 | N7: 17153.5 | O7: 15834.65 | P7: 17132.199 | Q7: 17132.199 | R7: 6349900 | S7: =P7/P6 -> 1.0868582 | T7: =S7-1 -> 0.086858154
A8: 44295 | B8: 14882.65 | C8: 14918.45 | D8: 14785.65 | E8: 14834.85 | F8: 14834.85 | G8: 504100 | H8: =(E8/E7) -> 0.99738129 | I8: =H8-1 -> -0.0026187119 | J8: =((E8-E7)/E7)*100 -> -0.26187119 | L8: 44440 | M8: 17185.6 | N8: 17947.65 | O8: 17055.051 | P8: 17618.15 | Q8: 17618.15 | R8: 6955600 | S8: =P8/P7 -> 1.0283648 | T8: =S8-1 -> 0.028364786
A9: 44298 | B9: 14644.65 | C9: 14652.5 | D9: 14248.7 | E9: 14310.8 | F9: 14310.8 | G9: 650200 | H9: =(E9/E8) -> 0.96467441 | I9: =H9-1 -> -0.035325589 | J9: =((E9-E8)/E8)*100 -> -3.5325589 | L9: 44470 | M9: 17531.9 | N9: 18604.449 | O9: 17452.9 | P9: 17671.65 | Q9: 17671.65 | R9: 7651200 | S9: =P9/P8 -> 1.0030366 | T9: =S9-1 -> 0.0030366411
A10: 44299 | B10: 14364.9 | C10: 14528.9 | D10: 14274.9 | E10: 14504.8 | F10: 14504.8 | G10: 605100 | H10: =(E10/E9) -> 1.0135562 | I10: =H10-1 -> 0.013556196 | J10: =((E10-E9)/E9)*100 -> 1.3556196 | L10: 44501 | M10: 17783.15 | N10: 18210.15 | O10: 16782.4 | P10: 16983.199 | Q10: 16983.199 | R10: 5853100 | S10: =P10/P9 -> 0.96104206 | T10: =S10-1 -> -0.038957944
A11: 44301 | B11: 14522.4 | C11: 14597.55 | D11: 14353.2 | E11: 14581.45 | F11: 14581.45 | G11: 568000 | H11: =(E11/E10) -> 1.0052845 | I11: =H11-1 -> 0.0052844845 | J11: =((E11-E10)/E10)*100 -> 0.52844845 | L11: 44531 | M11: 17104.4 | N11: 17639.5 | O11: 16410.199 | P11: 17354.051 | Q11: 17354.051 | R11: 5499300 | S11: =P11/P10 -> 1.0218364 | T11: =S11-1 -> 0.021836378
A12: 44302 | B12: 14599.6 | C12: 14697.7 | D12: 14559 | E12: 14617.85 | F12: 14617.85 | G12: 577200 | H12: =(E12/E11) -> 1.0024963 | I12: =H12-1 -> 0.0024962822 | J12: =((E12-E11)/E11)*100 -> 0.24962822 | L12: 44562 | M12: 17387.15 | N12: 18350.949 | O12: 16836.801 | P12: 17339.85 | Q12: 17339.85 | R12: 5435500 | S12: =P12/P11 -> 0.99918168 | T12: =S12-1 -> -0.0008183203
A13: 44305 | B13: 14306.6 | C13: 14382.3 | D13: 14191.4 | E13: 14359.45 | F13: 14359.45 | G13: 512300 | H13: =(E13/E12) -> 0.98232302 | I13: =H13-1 -> -0.017676979 | J13: =((E13-E12)/E12)*100 -> -1.7676979 | L13: 44593 | M13: 17529.449 | N13: 17794.6 | O13: 16203.25 | P13: 16793.9 | Q13: 16793.9 | R13: 5620100 | S13: =P13/P12 -> 0.96851477 | T13: =S13-1 -> -0.031485234
A14: 44306 | B14: 14526.7 | C14: 14526.95 | D14: 14207.3 | E14: 14296.4 | F14: 14296.4 | G14: 467400 | H14: =(E14/E13) -> 0.99560918 | I14: =H14-1 -> -0.004390823 | J14: =((E14-E13)/E13)*100 -> -0.4390823 | L14: 44621 | M14: 16593.1 | N14: 17559.801 | O14: 15671.45 | P14: 17464.75 | Q14: 17464.75 | R14: 7959500 | S14: =P14/P13 -> 1.039946 | T14: =S14-1 -> 0.039946028
A15: 44308 | B15: 14219.15 | C15: 14424.75 | D15: 14151.4 | E15: 14406.15 | F15: 14406.15 | G15: 524600 | H15: =(E15/E14) -> 1.0076768 | I15: =H15-1 -> 0.0076767576 | J15: =((E15-E14)/E14)*100 -> 0.76767576 | L15: 44652 | M15: 17436.9 | N15: 18114.65 | O15: 16824.699 | P15: 17102.551 | Q15: 17102.551 | R15: 5658100 | S15: =P15/P14 -> 0.97926113 | T15: =S15-1 -> -0.020738872
... A38: 44342 | B38: 15257.05 | C38: 15319.9 | D38: 15194.95 | E38: 15301.45 | F38: 15301.45 | G38: 384000 | H38: =(E38/E37) -> 1.006115 | I38: =H38-1 -> 0.0061150215 | J38: =((E38-E37)/E37)*100 -> 0.61150215 | L38: 45352 | M38: 22048.301 | N38: 22526.6 | O38: 21710.199 | P38: 22326.9 | Q38: 22326.9 | R38: 6700100 | S38: =P38/P37 -> 1.0156531 | T38: =S38-1 -> 0.015653129
A39: 44343 | B39: 15323.95 | C39: 15384.55 | D39: 15272.5 | E39: 15337.85 | F39: 15337.85 | G39: 0 | H39: =(E39/E38) -> 1.0023788 | I39: =H39-1 -> 0.0023788212 | J39: =((E39-E38)/E38)*100 -> 0.23788212
A40: 44344 | B40: 15421.2 | C40: 15469.65 | D40: 15394.75 | E40: 15435.65 | F40: 15435.65 | G40: 468100 | H40: =(E40/E39) -> 1.0063764 | I40: =H40-1 -> 0.0063764338 | J40: =((E40-E39)/E39)*100 -> 0.63764338
A41: 44347 | B41: 15437.75 | C41: 15606.35 | D41: 15374 | E41: 15582.8 | F41: 15582.8 | G41: 436000 | H41: =(E41/E40) -> 1.0095331 | I41: =H41-1 -> 0.009533088 | J41: =((E41-E40)/E40)*100 -> 0.9533088
A42: 44348 | B42: 15629.65 | C42: 15660.75 | D42: 15528.3 | E42: 15574.85 | F42: 15574.85 | G42: 409600 | H42: =(E42/E41) -> 0.99948981 | I42: =H42-1 -> -0.00051019047 | J42: =((E42-E41)/E41)*100 -> -0.051019047
A43: 44349 | B43: 15520.35 | C43: 15597.45 | D43: 15459.85 | E43: 15576.2 | F43: 15576.2 | G43: 428600 | H43: =(E43/E42) -> 1.0000867 | I43: =H43-1 -> 8.6715829e-05 | J43: =((E43-E42)/E42)*100 -> 0.0086715829
A44: 44350 | B44: 15655.55 | C44: 15705.1 | D44: 15611 | E44: 15690.35 | F44: 15690.35 | G44: 410200 | H44: =(E44/E43) -> 1.0073285 | I44: =H44-1 -> 0.0073284506 | J44: =((E44-E43)/E43)*100 -> 0.73284506
A45: 44351 | B45: 15712.5 | C45: 15733.6 | D45: 15622.35 | E45: 15670.25 | F45: 15670.25 | G45: 414200 | H45: =(E45/E44) -> 0.99871898 | I45: =H45-1 -> -0.0012810173 | J45: =((E45-E44)/E44)*100 -> -0.12810173
A46: 44354 | B46: 15725.1 | C46: 15773.45 | D46: 15678.1 | E46: 15751.65 | F46: 15751.65 | G46: 394000 | H46: =(E46/E45) -> 1.0051946 | I46: =H46-1 -> 0.0051945815 | J46: =((E46-E45)/E45)*100 -> 0.51945815
A47: 44355 | B47: 15773.9 | C47: 15778.8 | D47: 15680 | E47: 15740.1 | F47: 15740.1 | G47: 378200 | H47: =(E47/E46) -> 0.99926669 | I47: =H47-1 -> -0.00073330614 | J47: =((E47-E46)/E46)*100 -> -0.073330614
A48: 44356 | B48: 15766.3 | C48: 15800.45 | D48: 15566.9 | E48: 15635.35 | F48: 15635.35 | G48: 457900 | H48: =(E48/E47) -> 0.99334502 | I48: =H48-1 -> -0.0066549769 | J48: =((E48-E47)/E47)*100 -> -0.66549769
A49: 44357 | B49: 15692.1 | C49: 15751.25 | D49: 15648.5 | E49: 15737.75 | F49: 15737.75 | G49: 298300 | H49: =(E49/E48) -> 1.0065493 | I49: =H49-1 -> 0.0065492869 | J49: =((E49-E48)/E48)*100 -> 0.65492869
A50: 44358 | B50: 15796.45 | C50: 15835.55 | D50: 15749.8 | E50: 15799.35 | F50: 15799.35 | G50: 363000 | H50: =(E50/E49) -> 1.0039141 | I50: =H50-1 -> 0.0039141306 | J50: =((E50-E49)/E49)*100 -> 0.39141306
... A742: 45379 | B742: 22163.6 | C742: 22516 | D742: 22163.6 | E742: 22326.9 | F742: 22326.9 | G742: 410500 | H742: =(E742/E741) -> 1.009187 | I742: =H742-1 -> 0.0091870011 | J742: =((E742-E741)/E741)*100 -> 0.91870011

Sheet Descriptive Stats
C1: GRAPHS HERE
A2: Measures of Risk and Return | C2: Considering the exceptionally low volatility, minimal market correlation, and negative return measures, this stock is likely a: Stable-Value Stock: These stocks are known for their low volatility and reliable dividends. The minimal correlation with the market and low average daily return suggest this could be the case. However, the negative alpha and Sharpe Ratio indicate underperformance, which is not ideal for a value stock. Cash Equivalent: This is a possibility if the stock price barely moves and offers a return close to the risk-free rate (represented by the market return in this case). However, companies typically don't issue stock that behaves like a cash equivalent. Sharpe ratio (0.030) suggests a positive but modest risk-adjusted performance for the stock. This means the investment's returns are exceeding the risk-free rate, but the margin relative to its volatility is lower. A beta(0.082) this close to zero suggests the stock's price movements have minimal correlation with the market (represented by the market return) Standard Deviation (0.0294): This is exceptionally low, indicating extremely low volatility in the daily stock price movements. The difference in beta values for monthly (0.121) and daily sampling (0.081) suggests the stock's risk profile might be more sensitive to short-term market noise compared to its long-term fundamentals.
A3: Standard Deviation | B3: =stdev('Historical Data Daily'!J:J) -> 0.02936242
A4: Annualised Standard Deviation | B4: =B3*(365)^1/2 -> 5.3586416
A5: Mean | B5: =AVERAGE('Historical Data Daily'!J:J) -> 0.0012656677
A6: Beta Daily Sampling | B6: =COVAR('Historical Data Daily'!J3:J741,'NIFTY 50 '!I4:I742)/VAR('NIFTY 50 '!I4:I742) -> 0.93514318
A7: Beta Monthly Sampling | B7: =COVAR('Historical Data Monthly'!I2:I37,'NIFTY 50 '!T3:T38)/var('NIFTY 50 '!T3:T38) -> 1.6744687
A8: Sharpe Ratio | B8: =(B10-(B14/100))/B4 -> 0.030160201
A9: Alpha | B9: =B12 - (B14 + B6*(B13-B14)) -> -0.44927893
A10: Average Annual Return | B10: =('Historical Data Daily'!E741/'Historical Data Daily'!E2)^(1/3) -1 -> 0.23100024
A11: Coefficient of Variation | B11: =(B3/B5) -> 23.199154
A12: Average Return | B12: =AVERAGEA('Historical Data Daily'!J:J) -> 0.0012639574
A13: Market return | B13: =average('NIFTY 50 '!I:I) -> 0.00058793461
A14: Risk free rate | B14: =AVERAGE('Historical Data Daily'!V:V) -> 6.9382534
A17: Descriptive Stats on Close of the Company | C17: The standard deviation is 48.19, which is less than half the mean closing price of 133.42. This suggests that the stock may be relatively stable, with prices not fluctuating dramatically.
A18: Mean | B18: =AVERAGE('Historical Data Daily'!E2:E741) -> 133.41696
A19: Min Value | B19: =min('Historical Data Daily'!E2:E741) -> 68.300003
A20: Max Value | B20: =max('Historical Data Daily'!E2:E741) -> 280.54999
A21: Standard Deviation | B21: =STDEV('Historical Data Daily'!E2:E741) -> 48.186483
A24: Descriptive Stats on correlation of NIFTY 50 and Company's Stock Price | C24: Based on the correlation of 0.739, the company's stock price has a strong positive correlation with NIFTY 50. A correlation coefficient closer to 1 signifies a stronger positive correlation, meaning the stock price mostly moves in tandem with the NIFTY 50. Given the strong positive correlation, this stock appears to be a cyclical stock. Cyclical stocks tend to amplify the market's movements.
A25: Correlation | B25: =CORREL('Historical Data Daily'!E2:E741, 'NIFTY 50 '!E3:E742) -> 0.73835701
A28: Daily Movement in stock price (Spread: High-Low) | B28: ( Sentiment Analysis) | C28: Moderate Volatility: The stock exhibits moderate volatility, suggesting it's not a low-risk, stable investment but also not an extremely risky, high-fluctuation stock. Limited Sentiment Impact: The negligible correlation between sentiment analysis and price movement indicates that short-term price movements are likely driven by factors other than immediate corporate announcements. Based on the analysis, this stock could be: Growth Stock: These aim for high capital appreciation and might experience moderate volatility due to potential for high future earnings but uncertainty in the short term. Sectoral Stock: Its performance might be more tied to its industry's health than overall market sentiment.
A29: Mean | B29: =AVERAGE('Historical Data Daily'!K:K) -> 6.0075671
A30: Median | B30: =MEDIAN('Historical Data Daily'!K:K) -> 4.9000015
A31: Max Value | B31: =max('Historical Data Daily'!K:K) -> 35.399994
A32: Min Value | B32: =min('Historical Data Daily'!K:K) -> 0.949997
A33: Standard Deviation | B33: =stdev('Historical Data Daily'!K:K) -> 4.3134309
A34: Correlation between corporate announcements and volatility in a day | B34: =correl('Historical Data Daily'!K:K, 'Historical Data Daily'!Q:Q) -> 0.027374891
C36: DATE
A37: Lifetime High | B37: =max('Historical Data Daily'!C2:C741) -> 289.75 | C37: 45334
A38: Lifetime Low | B38: =min('Historical Data Daily'!D2:D741) -> 65.5 | C38: 44743
A39: 52 Week High | B39: =max('Historical Data Daily'!C499:C741) -> 289.75 | C39: 45334
A40: 52 Week Low | B40: =min('Historical Data Daily'!D499:D741) -> 74.400002 | C40: 44755
A44: Volatility of Stock | C44: In this case, with a weak positive correlation, the stock's price movements might be influenced by a combination of factors: Company Fundamentals, Industry Trends, Overall Market Conditions
A45: Correlation btw Volume and Change occurred in Stock Price | B45: =CORREL('Historical Data Daily'!N:N,'Historical Data Daily'!H:H) -> 0.489663
A48: TIme | B48: Daily Sampling | C48: Monthly Sampling | D48: 2021-2022: High daily beta (1.049) and a negative monthly beta (-0.003) indicate a complex relationship with the market. The investment might have been somewhat independent in the long term (negative monthly beta) but still susceptible to short-term market movements (high daily beta). The investment might have been in a growth phase or undergoing significant changes, leading to price movements not fully reflected in the overall market. 2022-2023 & 2023-2024: Both daily and monthly betas are very close to zero. This suggests the investment's price movements became largely independent of the market during these periods. The investment's fundamentals might have matured, or the market sector it operates in might have become less volatile. This could explain the near-zero beta, indicating minimal correlation with the market.
A49: 2021-2024 | B49: =B6 -> 0.93514318 | C49: =B7 -> 1.6744687
A50: 2021-2022 | B50: =COVAR('Historical Data Daily'!J2:J249,'NIFTY 50 '!I3:I250) / VAR('NIFTY 50 '!I3:I250) -> 1.049452 | C50: =COVAR('Historical Data Monthly'!E2:E13,'NIFTY 50 '!P3:P14) / VAR('NIFTY 50 '!P3:P14) -> -0.0032544937
A51: 2022-2023 | B51: =COVAR('Historical Data Daily'!E250:E498,'NIFTY 50 '!E251:E499)/var('NIFTY 50 '!E251:E499) -> 0.008999608 | C51: =COVAR('Historical Data Monthly'!E14:E25,'NIFTY 50 '!P15:P26) / VAR('NIFTY 50 '!P15:Z26) -> 1.0668364e-09
A52: 2023-2024 | B52: =COVAR('Historical Data Daily'!E499:E741,'NIFTY 50 '!E500:E742)/var('NIFTY 50 '!E500:E742) -> 0.031893889 | C52: =COVAR('Historical Data Monthly'!E14:E37,'NIFTY 50 '!P15:P38)/var('NIFTY 50 '!P15:P38) -> 0.02784931
...

Sheet Technical Analysis
M1: Date | N1: 10 SMA of Close | O1: Std Dev of Close | P1: EMA (26) | Q1: EMA (12) | R1: MACD | S1: Signal Line | T1: MACD-Signal Line | U1: Upper Band | V1: Lower Band
A2: STRATEGY | B2: TA Strategy | M2: 44287 | P2: 111.45 | Q2: 111.45 | R2: =Q2-P2 -> 0 | S2: 0 | T2: 0
M3: 44291 | P3: =('Historical Data Daily'!E3-P2)*'Historical Data Daily'!$S$13 + P2 -> 111.76852 | Q3: =('Historical Data Daily'!E3-Q2)*'Historical Data Daily'!$S$12 + Q2 -> 112.11154 | R3: =Q3-P3 -> 0.34302018 | S3: =(R3-S2)*'Historical Data Daily'!$S$14 + S2 -> 0.068604036 | T3: =R3-S3 -> 0.27441615
M4: 44292 | P4: =('Historical Data Daily'!E4-P3)*'Historical Data Daily'!$S$13 + P3 -> 112.05974 | Q4: =('Historical Data Daily'!E4-Q3)*'Historical Data Daily'!$S$12 + Q3 -> 112.66361 | R4: =Q4-P4 -> 0.60387028 | S4: =(R4-S3)*'Historical Data Daily'!$S$14 + S3 -> 0.17565729 | T4: =R4-S4 -> 0.428213
M5: 44293 | P5: =('Historical Data Daily'!E5-P4)*'Historical Data Daily'!$S$13 + P4 -> 112.27013 | Q5: =('Historical Data Daily'!E5-Q4)*'Historical Data Daily'!$S$12 + Q4 -> 113.00767 | R5: =Q5-P5 -> 0.73754104 | S5: =(R5-S4)*'Historical Data Daily'!$S$14 + S4 -> 0.28803404 | T5: =R5-S5 -> 0.44950701
M6: 44294 | P6: =('Historical Data Daily'!E6-P5)*'Historical Data Daily'!$S$13 + P5 -> 112.55752 | Q6: =('Historical Data Daily'!E6-Q5)*'Historical Data Daily'!$S$12 + Q5 -> 113.4911 | R6: =Q6-P6 -> 0.93357892 | S6: =(R6-S5)*'Historical Data Daily'!$S$14 + S5 -> 0.41714301 | T6: =R6-S6 -> 0.51643591
M7: 44295 | P7: =('Historical Data Daily'!E7-P6)*'Historical Data Daily'!$S$13 + P6 -> 112.84586 | Q7: =('Historical Data Daily'!E7-Q6)*'Historical Data Daily'!$S$12 + Q6 -> 113.94632 | R7: =Q7-P7 -> 1.100462 | S7: =(R7-S6)*'Historical Data Daily'!$S$14 + S6 -> 0.55380681 | T7: =R7-S7 -> 0.54665519
J8: PRICE MOVEMENT CHART | M8: 44298 | P8: =('Historical Data Daily'!E8-P7)*'Historical Data Daily'!$S$13 + P7 -> 112.22024 | Q8: =('Historical Data Daily'!E8-Q7)*'Historical Data Daily'!$S$12 + Q7 -> 112.47765 | R8: =Q8-P8 -> 0.25741681 | S8: =(R8-S7)*'Historical Data Daily'!$S$14 + S7 -> 0.49452881 | T8: =R8-S8 -> -0.237112
M9: 44299 | P9: =('Historical Data Daily'!E9-P8)*'Historical Data Daily'!$S$13 + P8 -> 111.99652 | Q9: =('Historical Data Daily'!E9-Q8)*'Historical Data Daily'!$S$12 + Q8 -> 111.9734 | R9: =Q9-P9 -> -0.023116623 | S9: =(R9-S8)*'Historical Data Daily'!$S$14 + S8 -> 0.39099972 | T9: =R9-S9 -> -0.41411635
M10: 44301 | P10: =('Historical Data Daily'!E10-P9)*'Historical Data Daily'!$S$13 + P9 -> 111.63381 | Q10: =('Historical Data Daily'!E10-Q9)*'Historical Data Daily'!$S$12 + Q9 -> 111.22365 | R10: =Q10-P10 -> -0.41016562 | S10: =(R10-S9)*'Historical Data Daily'!$S$14 + S9 -> 0.23076665 | T10: =R10-S10 -> -0.64093228
M11: 44302 | N11: =AVERAGE('Historical Data Daily'!E2:E11) -> 112.34 | O11: =STDEV('Historical Data Daily'!E2:E11) -> 4.2430858 | P11: =('Historical Data Daily'!E11-P10)*'Historical Data Daily'!$S$13 + P10 -> 111.68316 | Q11: =('Historical Data Daily'!E11-Q10)*'Historical Data Daily'!$S$12 + Q10 -> 111.38924 | R11: =Q11-P11 -> -0.29391968 | S11: =(R11-S10)*'Historical Data Daily'!$S$14 + S10 -> 0.12582939 | T11: =R11-S11 -> -0.41974906 | U11: =N11+O11*2 -> 120.82617 | V11: =N11-O11*2 -> 103.85383
M12: 44305 | N12: =AVERAGE('Historical Data Daily'!E3:E12) -> 112.05 | O12: =STDEV('Historical Data Daily'!E3:E12) -> 4.4066234 | P12: =('Historical Data Daily'!E12-P11)*'Historical Data Daily'!$S$13 + P11 -> 111.45107 | Q12: =('Historical Data Daily'!E12-Q11)*'Historical Data Daily'!$S$12 + Q11 -> 110.95243 | R12: =Q12-P12 -> -0.49863958 | S12: =(R12-S11)*'Historical Data Daily'!$S$14 + S11 -> 0.00093559457 | T12: =R12-S12 -> -0.49957517 | U12: =N12+O12*2 -> 120.86325 | V12: =N12-O12*2 -> 103.23675
M13: 44306 | N13: =AVERAGE('Historical Data Daily'!E4:E13) -> 111.165 | O13: =STDEV('Historical Data Daily'!E4:E13) -> 4.4692182 | P13: =('Historical Data Daily'!E13-P12)*'Historical Data Daily'!$S$13 + P12 -> 111.11396 | Q13: =('Historical Data Daily'!E13-Q12)*'Historical Data Daily'!$S$12 + Q12 -> 110.32898 | R13: =Q13-P13 -> -0.78497417 | S13: =(R13-S12)*'Historical Data Daily'!$S$14 + S12 -> -0.15624636 | T13: =R13-S13 -> -0.62872781 | U13: =N13+O13*2 -> 120.10344 | V13: =N13-O13*2 -> 102.22656
M14: 44308 | N14: =AVERAGE('Historical Data Daily'!E5:E14) -> 110.275 | O14: =STDEV('Historical Data Daily'!E5:E14) -> 4.3503668 | P14: =('Historical Data Daily'!E14-P13)*'Historical Data Daily'!$S$13 + P13 -> 110.7944 | Q14: =('Historical Data Daily'!E14-Q13)*'Historical Data Daily'!$S$12 + Q13 -> 109.78606 | R14: =Q14-P14 -> -1.0083419 | S14: =(R14-S13)*'Historical Data Daily'!$S$14 + S13 -> -0.32666548 | T14: =R14-S14 -> -0.68167647 | U14: =N14+O14*2 -> 118.97573 | V14: =N14-O14*2 -> 101.57427
M15: 44309 | N15: =AVERAGE('Historical Data Daily'!E6:E15) -> 109.96 | O15: =STDEV('Historical Data Daily'!E6:E15) -> 4.0841694 | P15: =('Historical Data Daily'!E15-P14)*'Historical Data Daily'!$S$13 + P14 -> 110.86519 | Q15: =('Historical Data Daily'!E15-Q14)*'Historical Data Daily'!$S$12 + Q14 -> 110.08821 | R15: =Q15-P15 -> -0.77698256 | S15: =(R15-S14)*'Historical Data Daily'!$S$14 + S14 -> -0.41672889 | T15: =R15-S15 -> -0.36025367 | U15: =N15+O15*2 -> 118.12834 | V15: =N15-O15*2 -> 101.79166
M16: 44312 | N16: =AVERAGE('Historical Data Daily'!E7:E16) -> 109.775 | O16: =STDEV('Historical Data Daily'!E7:E16) -> 3.8049852 | P16: =('Historical Data Daily'!E16-P15)*'Historical Data Daily'!$S$13 + P15 -> 111.11962 | Q16: =('Historical Data Daily'!E16-Q15)*'Historical Data Daily'!$S$12 + Q15 -> 110.73618 | R16: =Q16-P16 -> -0.38344454 | S16: =(R16-S15)*'Historical Data Daily'!$S$14 + S15 -> -0.41007202 | T16: =R16-S16 -> 0.026627486 | U16: =N16+O16*2 -> 117.38497 | V16: =N16-O16*2 -> 102.16503
M17: 44313 | N17: =AVERAGE('Historical Data Daily'!E8:E17) -> 109.32 | O17: =STDEV('Historical Data Daily'!E8:E17) -> 3.1303358 | P17: =('Historical Data Daily'!E17-P16)*'Historical Data Daily'!$S$13 + P16 -> 111.17743 | Q17: =('Historical Data Daily'!E17-Q16)*'Historical Data Daily'!$S$12 + Q16 -> 110.91523 | R17: =Q17-P17 -> -0.26220036 | S17: =(R17-S16)*'Historical Data Daily'!$S$14 + S16 -> -0.38049769 | T17: =R17-S17 -> 0.11829733 | U17: =N17+O17*2 -> 115.58067 | V17: =N17-O17*2 -> 103.05933
M18: 44314 | N18: =AVERAGE('Historical Data Daily'!E9:E18) -> 110.295 | O18: =STDEV('Historical Data Daily'!E9:E18) -> 2.9402812 | P18: =('Historical Data Daily'!E18-P17)*'Historical Data Daily'!$S$13 + P17 -> 111.39762 | Q18: =('Historical Data Daily'!E18-Q17)*'Historical Data Daily'!$S$12 + Q17 -> 111.41288 | R18: =Q18-P18 -> 0.015266738 | S18: =(R18-S17)*'Historical Data Daily'!$S$14 + S17 -> -0.3013448 | T18: =R18-S18 -> 0.31661154 | U18: =N18+O18*2 -> 116.17556 | V18: =N18-O18*2 -> 104.41444
M19: 44315 | N19: =AVERAGE('Historical Data Daily'!E10:E19) -> 110.58 | O19: =STDEV('Historical Data Daily'!E10:E19) -> 2.9604059 | P19: =('Historical Data Daily'!E19-P18)*'Historical Data Daily'!$S$13 + P18 -> 111.44594 | Q19: =('Historical Data Daily'!E19-Q18)*'Historical Data Daily'!$S$12 + Q18 -> 111.5109 | R19: =Q19-P19 -> 0.064960221 | S19: =(R19-S18)*'Historical Data Daily'!$S$14 + S18 -> -0.2280838 | T19: =R19-S19 -> 0.29304402 | U19: =N19+O19*2 -> 116.50081 | V19: =N19-O19*2 -> 104.65919
M20: 44316 | N20: =AVERAGE('Historical Data Daily'!E11:E20) -> 111.04 | O20: =STDEV('Historical Data Daily'!E11:E20) -> 2.7060424 | P20: =('Historical Data Daily'!E20-P19)*'Historical Data Daily'!$S$13 + P19 -> 111.46476 | Q20: =('Historical Data Daily'!E20-Q19)*'Historical Data Daily'!$S$12 + Q19 -> 111.53999 | R20: =Q20-P20 -> 0.075232867 | S20: =(R20-S19)*'Historical Data Daily'!$S$14 + S19 -> -0.16742047 | T20: =R20-S20 -> 0.24265333 | U20: =N20+O20*2 -> 116.45209 | V20: =N20-O20*2 -> 105.62792
M21: 44319 | N21: =AVERAGE('Historical Data Daily'!E12:E21) -> 111.205 | O21: =STDEV('Historical Data Daily'!E12:E21) -> 2.83847 | P21: =('Historical Data Daily'!E21-P20)*'Historical Data Daily'!$S$13 + P20 -> 111.64885 | Q21: =('Historical Data Daily'!E21-Q20)*'Historical Data Daily'!$S$12 + Q20 -> 111.91076 | R21: =Q21-P21 -> 0.26191106 | S21: =(R21-S20)*'Historical Data Daily'!$S$14 + S20 -> -0.08155416 | T21: =R21-S21 -> 0.34346522 | U21: =N21+O21*2 -> 116.88194 | V21: =N21-O21*2 -> 105.52806
M22: 44320 | N22: =AVERAGE('Historical Data Daily'!E13:E22) -> 111.885 | O22: =STDEV('Historical Data Daily'!E13:E22) -> 2.9443014 | P22: =('Historical Data Daily'!E22-P21)*'Historical Data Daily'!$S$13 + P21 -> 111.92301 | Q22: =('Historical Data Daily'!E22-Q21)*'Historical Data Daily'!$S$12 + Q21 -> 112.43988 | R22: =Q22-P22 -> 0.51686516 | S22: =(R22-S21)*'Historical Data Daily'!$S$14 + S21 -> 0.038129703 | T22: =R22-S22 -> 0.47873545 | U22: =N22+O22*2 -> 117.7736 | V22: =N22-O22*2 -> 105.9964
... M35: 44340 | N35: =AVERAGE('Historical Data Daily'!E26:E35) -> 143.715 | O35: =STDEV('Historical Data Daily'!E26:E35) -> 3.5863202 | P35: =('Historical Data Daily'!E35-P34)*'Historical Data Daily'!$S$13 + P34 -> 131.16212 | Q35: =('Historical Data Daily'!E35-Q34)*'Historical Data Daily'!$S$12 + Q34 -> 139.06969 | R35: =Q35-P35 -> 7.9075726 | S35: =(R35-S34)*'Historical Data Daily'!$S$14 + S34 -> 7.7651296 | T35: =R35-S35 -> 0.14244301 | U35: =N35+O35*2 -> 150.88764 | V35: =N35-O35*2 -> 136.54236
J36: Bollinger Bands | M36: 44341 | N36: =AVERAGE('Historical Data Daily'!E27:E36) -> 144.48 | O36: =STDEV('Historical Data Daily'!E27:E36) -> 2.9280442 | P36: =('Historical Data Daily'!E36-P35)*'Historical Data Daily'!$S$13 + P35 -> 132.21677 | Q36: =('Historical Data Daily'!E36-Q35)*'Historical Data Daily'!$S$12 + Q35 -> 140.04358 | R36: =Q36-P36 -> 7.826808 | S36: =(R36-S35)*'Historical Data Daily'!$S$14 + S35 -> 7.7774652 | T36: =R36-S36 -> 0.04934274 | U36: =N36+O36*2 -> 150.33609 | V36: =N36-O36*2 -> 138.62391
M37: 44342 | N37: =AVERAGE('Historical Data Daily'!E28:E37) -> 143.88 | O37: =STDEV('Historical Data Daily'!E28:E37) -> 3.0572482 | P37: =('Historical Data Daily'!E37-P36)*'Historical Data Daily'!$S$13 + P36 -> 132.83775 | Q37: =('Historical Data Daily'!E37-Q36)*'Historical Data Daily'!$S$12 + Q36 -> 140.12919 | R37: =Q37-P37 -> 7.2914315 | S37: =(R37-S36)*'Historical Data Daily'!$S$14 + S36 -> 7.6802585 | T37: =R37-S37 -> -0.38882702 | U37: =N37+O37*2 -> 149.9945 | V37: =N37-O37*2 -> 137.7655
M38: 44343 | N38: =AVERAGE('Historical Data Daily'!E29:E38) -> 143.03 | O38: =STDEV('Historical Data Daily'!E29:E38) -> 2.3817822 | P38: =('Historical Data Daily'!E38-P37)*'Historical Data Daily'!$S$13 + P37 -> 133.45348 | Q38: =('Historical Data Daily'!E38-Q37)*'Historical Data Daily'!$S$12 + Q37 -> 140.28623 | R38: =Q38-P38 -> 6.8327574 | S38: =(R38-S37)*'Historical Data Daily'!$S$14 + S37 -> 7.5107583 | T38: =R38-S38 -> -0.67800088 | U38: =N38+O38*2 -> 147.79356 | V38: =N38-O38*2 -> 138.26643
M39: 44344 | N39: =AVERAGE('Historical Data Daily'!E30:E39) -> 142.245 | O39: =STDEV('Historical Data Daily'!E30:E39) -> 2.6627526 | P39: =('Historical Data Daily'!E39-P38)*'Historical Data Daily'!$S$13 + P38 -> 133.78285 | Q39: =('Historical Data Daily'!E39-Q38)*'Historical Data Daily'!$S$12 + Q38 -> 139.91912 | R39: =Q39-P39 -> 6.1362719 | S39: =(R39-S38)*'Historical Data Daily'!$S$14 + S38 -> 7.235861 | T39: =R39-S39 -> -1.0995891 | U39: =N39+O39*2 -> 147.5705 | V39: =N39-O39*2 -> 136.91949
M40: 44347 | N40: =AVERAGE('Historical Data Daily'!E31:E40) -> 141.08 | O40: =STDEV('Historical Data Daily'!E31:E40) -> 2.999924 | P40: =('Historical Data Daily'!E40-P39)*'Historical Data Daily'!$S$13 + P39 -> 133.88042 | Q40: =('Historical Data Daily'!E40-Q39)*'Historical Data Daily'!$S$12 + Q39 -> 139.17772 | R40: =Q40-P40 -> 5.2973025 | S40: =(R40-S39)*'Historical Data Daily'!$S$14 + S39 -> 6.8481493 | T40: =R40-S40 -> -1.5508468 | U40: =N40+O40*2 -> 147.07985 | V40: =N40-O40*2 -> 135.08015
M41: 44348 | N41: =AVERAGE('Historical Data Daily'!E32:E41) -> 140.68 | O41: =STDEV('Historical Data Daily'!E32:E41) -> 2.8912865 | P41: =('Historical Data Daily'!E41-P40)*'Historical Data Daily'!$S$13 + P40 -> 134.30409 | Q41: =('Historical Data Daily'!E41-Q40)*'Historical Data Daily'!$S$12 + Q40 -> 139.24269 | R41: =Q41-P41 -> 4.9385965 | S41: =(R41-S40)*'Historical Data Daily'!$S$14 + S40 -> 6.4662387 | T41: =R41-S41 -> -1.5276422 | U41: =N41+O41*2 -> 146.46257 | V41: =N41-O41*2 -> 134.89743
M42: 44349 | N42: =AVERAGE('Historical Data Daily'!E33:E42) -> 140.305 | O42: =STDEV('Historical Data Daily'!E33:E42) -> 2.6218553 | P42: =('Historical Data Daily'!E42-P41)*'Historical Data Daily'!$S$13 + P41 -> 134.75564 | Q42: =('Historical Data Daily'!E42-Q41)*'Historical Data Daily'!$S$12 + Q41 -> 139.42073 | R42: =Q42-P42 -> 4.6650955 | S42: =(R42-S41)*'Historical Data Daily'!$S$14 + S41 -> 6.1060101 | T42: =R42-S42 -> -1.4409146 | U42: =N42+O42*2 -> 145.54871 | V42: =N42-O42*2 -> 135.06129
M43: 44350 | N43: =AVERAGE('Historical Data Daily'!E34:E43) -> 140.185 | O43: =STDEV('Historical Data Daily'!E34:E43) -> 2.619057 | P43: =('Historical Data Daily'!E43-P42)*'Historical Data Daily'!$S$13 + P42 -> 135.12189 | Q43: =('Historical Data Daily'!E43-Q42)*'Historical Data Daily'!$S$12 + Q42 -> 139.4637 | R43: =Q43-P43 -> 4.3418104 | S43: =(R43-S42)*'Historical Data Daily'!$S$14 + S42 -> 5.7531702 | T43: =R43-S43 -> -1.4113598 | U43: =N43+O43*2 -> 145.42311 | V43: =N43-O43*2 -> 134.94689
M44: 44351 | N44: =AVERAGE('Historical Data Daily'!E35:E44) -> 140.055 | O44: =STDEV('Historical Data Daily'!E35:E44) -> 2.6311622 | P44: =('Historical Data Daily'!E44-P43)*'Historical Data Daily'!$S$13 + P43 -> 135.42767 | Q44: =('Historical Data Daily'!E44-Q43)*'Historical Data Daily'!$S$12 + Q43 -> 139.43082 | R44: =Q44-P44 -> 4.0031478 | S44: =(R44-S43)*'Historical Data Daily'!$S$14 + S43 -> 5.4031657 | T44: =R44-S44 -> -1.4000179 | U44: =N44+O44*2 -> 145.31732 | V44: =N44-O44*2 -> 134.79267
M45: 44354 | N45: =AVERAGE('Historical Data Daily'!E36:E45) -> 139.785 | O45: =STDEV('Historical Data Daily'!E36:E45) -> 2.6105583 | P45: =('Historical Data Daily'!E45-P44)*'Historical Data Daily'!$S$13 + P44 -> 135.67377 | Q45: =('Historical Data Daily'!E45-Q44)*'Historical Data Daily'!$S$12 + Q44 -> 139.32608 | R45: =Q45-P45 -> 3.6523079 | S45: =(R45-S44)*'Historical Data Daily'!$S$14 + S44 -> 5.0529941 | T45: =R45-S45 -> -1.4006862 | U45: =N45+O45*2 -> 145.00612 | V45: =N45-O45*2 -> 134.56388
M46: 44355 | N46: =AVERAGE('Historical Data Daily'!E37:E46) -> 139.33 | O46: =STDEV('Historical Data Daily'!E37:E46) -> 1.791057 | P46: =('Historical Data Daily'!E46-P45)*'Historical Data Daily'!$S$13 + P45 -> 136.0572 | Q46: =('Historical Data Daily'!E46-Q45)*'Historical Data Daily'!$S$12 + Q45 -> 139.56053 | R46: =Q46-P46 -> 3.5033334 | S46: =(R46-S45)*'Historical Data Daily'!$S$14 + S45 -> 4.743062 | T46: =R46-S46 -> -1.2397286 | U46: =N46+O46*2 -> 142.91211 | V46: =N46-O46*2 -> 135.74789
M47: 44356 | N47: =AVERAGE('Historical Data Daily'!E38:E47) -> 139.16 | O47: =STDEV('Historical Data Daily'!E38:E47) -> 1.7369818 | P47: =('Historical Data Daily'!E47-P46)*'Historical Data Daily'!$S$13 + P46 -> 136.26777 | Q47: =('Historical Data Daily'!E47-Q46)*'Historical Data Daily'!$S$12 + Q46 -> 139.45891 | R47: =Q47-P47 -> 3.191135 | S47: =(R47-S46)*'Historical Data Daily'!$S$14 + S46 -> 4.4326766 | T47: =R47-S47 -> -1.2415416 | U47: =N47+O47*2 -> 142.63396 | V47: =N47-O47*2 -> 135.68604
M48: 44357 | N48: =AVERAGE('Historical Data Daily'!E39:E48) -> 139.23 | O48: =STDEV('Historical Data Daily'!E39:E48) -> 1.837299 | P48: =('Historical Data Daily'!E48-P47)*'Historical Data Daily'!$S$13 + P47 -> 136.68127 | Q48: =('Historical Data Daily'!E48-Q47)*'Historical Data Daily'!$S$12 + Q47 -> 139.82677 | R48: =Q48-P48 -> 3.1454975 | S48: =(R48-S47)*'Historical Data Daily'!$S$14 + S47 -> 4.1752408 | T48: =R48-S48 -> -1.0297433 | U48: =N48+O48*2 -> 142.9046 | V48: =N48-O48*2 -> 135.5554
